<?xml version="1.0"?>
<robot xmlns:xacro="http://www.ros.org/wiki/xacro" name="cartesian">

    <xacro:include filename="urdf_include.xacro" />

    <link name="world" />
    <joint name="joint1" type="fixed">
        <parent link="world" />
        <child link="joint1_link" />
        <origin xyz="1.5 1.0 0.5" rpy="0 0 0" />
        <limit lower="0" upper="0.5" velocity="100" effort="100"/> 
    </joint>


    <xacro:property name="arm_length" value="1" />
    <link name="joint1_link">
        <visual>
            <origin rpy="0 0 0" xyz="0 0 0" />
            <geometry>
                <box size="0.1 0.1 ${arm_length}" />
            </geometry>
            <material name="blue">
                <color rgba="0 0 1 1" />
            </material>
        </visual>
        <collision>
            <origin rpy="0 0 0" xyz="0 0 0" />
            <geometry>
                <box size="0.1 0.1 ${arm_length}" />
            </geometry>
        </collision>
    </link>

    <joint name="joint2" type="prismatic">
        <origin xyz="-0.45 0.1  0.45" rpy="0 0 0" />
        <parent link="joint1_link" />
        <child link="joint2_link" />
        <axis xyz="1 0 0"/>
        <limit effort="100" velocity="1" lower="0" upper="0.8" />
    </joint>
    <link name="joint2_link">
        <visual>
            <origin rpy="0 0 0" xyz="0 0 0" />
            <geometry>
                <box size="${arm_length} 0.1 0.1" />
            </geometry>
            <material name="green">
                <color rgba="0.2 1 0.2 1" />
            </material>
        </visual>
        <collision>
            <origin rpy="0 0 0" xyz="0 0 0" />
            <geometry>
                <box size="${arm_length} 0.1 0.1" />
            </geometry>
        </collision>
    </link>
    <joint name="joint3" type="prismatic">
        <origin xyz="-0.45 0.45  0.1" rpy="0 0 0" />
        <parent link="joint2_link" />
        <child link="joint3_link" />
        <axis xyz="0 1 0"/>
        <limit effort="100" velocity="1" lower="0" upper="-0.8" />
    </joint>
    <link name="joint3_link">
        <visual>
            <origin rpy="0 0 0" xyz="0 0 0" />
            <geometry>
                <box size="0.1 ${arm_length} 0.1" />
            </geometry>
            <material name="blue">
                <color rgba="0 0 1 1" />
            </material>
        </visual>
        <collision>
            <origin rpy="0 0 0" xyz="0 0 0" />
            <geometry>
                <box size="0.1 ${arm_length} 0.1" />
            </geometry>
        </collision>
    </link>
    <joint name="joint4" type="prismatic">
        <origin xyz="0.1 0.45  -0.20" rpy="0 0 0" />
        <parent link="joint3_link" />
        <child link="end_link" />
        <axis xyz="0 0 1"/>
        <limit effort="100" velocity="1" lower="0" upper="0.4" />
    </joint>

    <xacro:property name="ender_length" value="0.5" />

    <link name="end_link">
        <visual>
            <origin rpy="0 0 0" xyz="0 0 0" />
            <geometry>
                <box size="0.1 0.1 ${ender_length}" />
            </geometry>
            <material name="green">
                <color rgba="0.2 1 0.2 1" />
            </material>
        </visual>
        <collision>
            <origin rpy="0 0 0" xyz="0 0 0" />
            <geometry>
                <box size="0.1 0.1 ${ender_length}" />
            </geometry>
        </collision>
    </link>

</robot>